<?xml version="1.0" ?>
<!-- =================================================================================== -->
<!-- |    This document was autogenerated by xacro from ros_ship.urdf.xacro            | -->
<!-- |    EDITING THIS FILE BY HAND IS NOT RECOMMENDED                                 | -->
<!-- =================================================================================== -->
<robot name="ros_ship" xmlns:xacro="http://ros.org/wiki/xacro">
  <link name="base_footprint"/>
  <joint name="base_link_joint" type="fixed">
    <origin xyz="0 0 0.3"/>
    <parent link="base_footprint"/>
    <child link="base_link"/>
  </joint>
  <link name="base_link">
    <visual>
      <geometry>
        <mesh filename="package://ros_ship_description/mesh/ROS_SHIP.dae"/>
      </geometry>
    </visual>
    <collision>
      <geometry>
        <mesh filename="package://ros_ship_description/mesh/ROS_SHIP.dae"/>
      </geometry>
    </collision>
    <pose>0 0 0 0 0 0</pose>
    <inertial>
      <mass value="95.7802"/>
      <inertia ixx="726786.15328170" ixy="2487.53795099" ixz="-56595.74202398" iyy="733701.84185624" iyz="12924.84782345" izz="-28558.50638870"/>
    </inertial>
  </link>
  <joint name="velodyne_joint" type="fixed">
    <origin xyz="1.4 0 0.55"/>
    <parent link="base_link"/>
    <child link="velodyne"/>
  </joint>
  <link name="velodyne">
    <visual>
      <geometry>
        <mesh filename="package://ros_ship_description/mesh/VLP-16.dae"/>
      </geometry>
    </visual>
    <collision>
      <geometry>
        <mesh filename="package://ros_ship_description/mesh/VLP-16.dae"/>
      </geometry>
    </collision>
  </link>
  <joint name="camera_r_joint" type="fixed">
    <origin xyz="1.6 -0.06 0.21"/>
    <parent link="base_link"/>
    <child link="camera_r"/>
  </joint>
  <link name="camera_r">
    <visual>
      <geometry>
        <mesh filename="package://ros_ship_description/mesh/CAMERA.dae"/>
      </geometry>
    </visual>
    <collision>
      <geometry>
        <mesh filename="package://ros_ship_description/mesh/CAMERA.dae"/>
      </geometry>
    </collision>
  </link>
  <joint name="camera_l_joint" type="fixed">
    <origin xyz="1.6 0.06 0.21"/>
    <parent link="base_link"/>
    <child link="camera_l"/>
  </joint>
  <link name="camera_l">
    <visual>
      <geometry>
        <mesh filename="package://ros_ship_description/mesh/CAMERA.dae"/>
      </geometry>
    </visual>
    <collision>
      <geometry>
        <mesh filename="package://ros_ship_description/mesh/CAMERA.dae"/>
      </geometry>
    </collision>
  </link>
  <joint name="motor_r_joint" type="fixed">
    <origin rpy="0 0 3.14159265359" xyz="-0.85 -0.325 -0.15"/>
    <parent link="base_link"/>
    <child link="motor_r"/>
  </joint>
  <link name="motor_r">
    <visual>
      <geometry>
        <mesh filename="package://ros_ship_description/mesh/MOTOR.dae"/>
      </geometry>
    </visual>
    <collision>
      <geometry>
        <mesh filename="package://ros_ship_description/mesh/MOTOR.dae"/>
      </geometry>
    </collision>
  </link>
  <joint name="propeller_r_joint" type="continuous">
    <origin xyz="0.17 0 0.026"/>
    <parent link="motor_r"/>
    <child link="propeller_r"/>
  </joint>
  <link name="propeller_r">
    <visual>
      <geometry>
        <mesh filename="package://ros_ship_description/mesh/PROPELLER.dae"/>
      </geometry>
    </visual>
    <collision>
      <geometry>
        <mesh filename="package://ros_ship_description/mesh/PROPELLER.dae"/>
      </geometry>
    </collision>
  </link>
  <joint name="motor_l_joint" type="fixed">
    <origin rpy="0 0 3.14159265359" xyz="-0.85 0.325 -0.15"/>
    <parent link="base_link"/>
    <child link="motor_l"/>
  </joint>
  <link name="motor_l">
    <visual>
      <geometry>
        <mesh filename="package://ros_ship_description/mesh/MOTOR.dae"/>
      </geometry>
    </visual>
    <collision>
      <geometry>
        <mesh filename="package://ros_ship_description/mesh/MOTOR.dae"/>
      </geometry>
    </collision>
  </link>
  <joint name="propeller_l_joint" type="continuous">
    <origin xyz="0.17 0 0.026"/>
    <parent link="motor_l"/>
    <child link="propeller_l"/>
  </joint>
  <link name="propeller_l">
    <visual>
      <geometry>
        <mesh filename="package://ros_ship_description/mesh/PROPELLER.dae"/>
      </geometry>
    </visual>
    <collision>
      <geometry>
        <mesh filename="package://ros_ship_description/mesh/PROPELLER.dae"/>
      </geometry>
    </collision>
  </link>
</robot>

