<?xml version="1.0" ?>
<!-- =================================================================================== -->
<!-- |    This document was autogenerated by xacro from ros_ship.urdf.xacro            | -->
<!-- |    EDITING THIS FILE BY HAND IS NOT RECOMMENDED                                 | -->
<!-- =================================================================================== -->
<robot name="ros_ship" xmlns:xacro="http://ros.org/wiki/xacro">
  <link name="base_footprint"/>
  <joint name="base_link_joint" type="fixed">
    <origin xyz="0 0 0.3"/>
    <parent link="base_footprint"/>
    <child link="base_link"/>
  </joint>
  <link name="base_link">
    <visual>
      <geometry>
        <mesh filename="package://ros_ship_description/mesh/ROS_SHIP.dae"/>
      </geometry>
    </visual>
    <collision name="base_link_collision">
      <geometry>
        <mesh filename="package://ros_ship_description/mesh/ROS_SHIP.dae"/>
      </geometry>
    </collision>
    <inertial>
      <mass value="95.7802"/>
      <inertia ixx="57.28" ixy="0.00" ixz="-0.23" iyy="57.28" iyz="0.00" izz="6.09"/>
    </inertial>
    <center_of_buoyancy>0.0 0.0 -0.3</center_of_buoyancy>
    <hydrodynamic_model>
      <type>fossen</type>
      <!-- Added mass: see p.28 in Berg2012 -->
      <added_mass>
           779.79 -6.8773 -103.32  8.5426 -165.54 -7.8033
          -6.8773    1222   51.29  409.44 -5.8488  62.726
          -103.32   51.29  3659.9  6.1112 -386.42  10.774
           8.5426  409.44  6.1112   534.9 -10.027  21.019
          -165.54 -5.8488 -386.42 -10.027  842.69 -1.1162
          -7.8033  62.726  10.775  21.019 -1.1162  224.32
      </added_mass>
      <!-- Linear damping: see p.31 in Berg2012 -->
      <linear_damping>
          -74.82 -69.48 -728.4 -268.8 -309.77 -105
      </linear_damping>
      <!-- Non-linear damping: see p.30 in Berg2012 -->
      <quadratic_damping>
          -748.22 -992.53 -1821.01 -672 -774.44 -523.27
      </quadratic_damping>
    </hydrodynamic_model>
  </link>
  <joint name="velodyne_base_mount_joint" type="fixed">
    <origin rpy="0 0 0" xyz="1.4 0 0.55"/>
    <parent link="base_link"/>
    <child link="velodyne_base_link"/>
  </joint>
  <link name="velodyne_base_link">
    <inertial>
      <mass value="0.1"/>
      <origin xyz="0 0 0"/>
      <inertia ixx="0.1" ixy="0" ixz="0" iyy="0.1" iyz="0" izz="0.1"/>
    </inertial>
    <visual>
      <geometry>
        <mesh filename="package://velodyne_description/meshes/VLP16_base_1.dae"/>
      </geometry>
    </visual>
    <visual>
      <geometry>
        <mesh filename="package://velodyne_description/meshes/VLP16_base_2.dae"/>
      </geometry>
    </visual>
    <collision>
      <origin rpy="0 0 0" xyz="0 0 0.03585"/>
      <geometry>
        <cylinder length="0.0717" radius="0.0516"/>
      </geometry>
    </collision>
  </link>
  <joint name="velodyne_base_scan_joint" type="fixed">
    <origin rpy="0 0 0" xyz="0 0 0.0377"/>
    <parent link="velodyne_base_link"/>
    <child link="velodyne"/>
  </joint>
  <link name="velodyne">
    <inertial>
      <mass value="0.1"/>
      <origin xyz="0 0 0"/>
      <inertia ixx="0.1" ixy="0" ixz="0" iyy="0.1" iyz="0" izz="0.1"/>
    </inertial>
    <visual>
      <origin xyz="0 0 -0.0377"/>
      <geometry>
        <mesh filename="package://velodyne_description/meshes/VLP16_scan.dae"/>
      </geometry>
    </visual>
  </link>
  <!-- Gazebo requires the velodyne_gazebo_plugins package -->
  <gazebo reference="velodyne">
    <sensor name="velodyne-VLP16" type="ray">
      <pose>0 0 0 0 0 0</pose>
      <visualize>false</visualize>
      <update_rate>10</update_rate>
      <ray>
        <scan>
          <horizontal>
            <samples>1875</samples>
            <resolution>1</resolution>
            <min_angle>-3.14159265359</min_angle>
            <max_angle> 3.14159265359</max_angle>
          </horizontal>
          <vertical>
            <samples>16</samples>
            <resolution>1</resolution>
            <min_angle>-0.261799387799</min_angle>
            <max_angle> 0.261799387799</max_angle>
          </vertical>
        </scan>
        <range>
          <min>0.055</min>
          <max>140.0</max>
          <resolution>0.001</resolution>
        </range>
        <noise>
          <type>gaussian</type>
          <mean>0.0</mean>
          <stddev>0.0</stddev>
        </noise>
      </ray>
      <plugin filename="libgazebo_ros_velodyne_laser.so" name="gazebo_ros_laser_controller">
        <topicName>/velodyne_points</topicName>
        <frameName>/velodyne</frameName>
        <min_range>0.9</min_range>
        <max_range>130.0</max_range>
        <gaussianNoise>0.008</gaussianNoise>
      </plugin>
    </sensor>
  </gazebo>
  <joint name="camera_r_joint" type="fixed">
    <origin xyz="1.6 -0.06 0.21"/>
    <parent link="base_link"/>
    <child link="camera_r"/>
  </joint>
  <link name="camera_r">
    <visual>
      <geometry>
        <mesh filename="package://ros_ship_description/mesh/CAMERA.dae"/>
      </geometry>
    </visual>
    <collision name="camera_r_collision">
      <geometry>
        <mesh filename="package://ros_ship_description/mesh/CAMERA.dae"/>
      </geometry>
    </collision>
    <inertial>
      <mass value="0.01"/>
      <inertia ixx="0.00" ixy="0.00" ixz="0.00" iyy="0.00" iyz="0.00" izz="0.00"/>
    </inertial>
  </link>
  <joint name="camera_l_joint" type="fixed">
    <origin xyz="1.6 0.06 0.21"/>
    <parent link="base_link"/>
    <child link="camera_l"/>
  </joint>
  <link name="camera_l">
    <visual>
      <geometry>
        <mesh filename="package://ros_ship_description/mesh/CAMERA.dae"/>
      </geometry>
    </visual>
    <collision name="camera_l_collision">
      <geometry>
        <mesh filename="package://ros_ship_description/mesh/CAMERA.dae"/>
      </geometry>
    </collision>
    <inertial>
      <mass value="0.01"/>
      <inertia ixx="0.00" ixy="0.00" ixz="0.00" iyy="0.00" iyz="0.00" izz="0.00"/>
    </inertial>
  </link>
  <joint name="motor_r_joint" type="fixed">
    <origin rpy="0 0 3.14159265359" xyz="-0.85 -0.325 -0.15"/>
    <parent link="base_link"/>
    <child link="motor_r"/>
  </joint>
  <link name="motor_r">
    <visual>
      <geometry>
        <mesh filename="package://ros_ship_description/mesh/MOTOR.dae"/>
      </geometry>
    </visual>
    <collision name="motor_r_collision">
      <geometry>
        <mesh filename="package://ros_ship_description/mesh/MOTOR.dae"/>
      </geometry>
    </collision>
    <inertial>
      <mass value="0.28"/>
      <inertia ixx="0.0001" ixy="0.00" ixz="0.00" iyy="0.0001" iyz="0.00" izz="0.0001"/>
    </inertial>
  </link>
  <joint name="propeller_r_joint" type="continuous">
    <origin rpy="0 0 3.14159265359" xyz="0.17 0 0.026"/>
    <parent link="motor_r"/>
    <child link="propeller_r"/>
  </joint>
  <link name="propeller_r">
    <visual>
      <geometry>
        <mesh filename="package://ros_ship_description/mesh/PROPELLER.dae"/>
      </geometry>
    </visual>
    <collision name="propeller_r_collision">
      <geometry>
        <mesh filename="package://ros_ship_description/mesh/PROPELLER.dae"/>
      </geometry>
    </collision>
    <inertial>
      <mass value="0.28"/>
      <inertia ixx="0.00086" ixy="0.00" ixz="0.00" iyy="0.00086" iyz="0.00" izz="0.0017"/>
    </inertial>
  </link>
  <joint name="motor_l_joint" type="fixed">
    <origin rpy="0 0 3.14159265359" xyz="-0.85 0.325 -0.15"/>
    <parent link="base_link"/>
    <child link="motor_l"/>
  </joint>
  <link name="motor_l">
    <visual>
      <geometry>
        <mesh filename="package://ros_ship_description/mesh/MOTOR.dae"/>
      </geometry>
    </visual>
    <collision name="motor_r_collision">
      <geometry>
        <mesh filename="package://ros_ship_description/mesh/MOTOR.dae"/>
      </geometry>
    </collision>
    <inertial>
      <mass value="0.28"/>
      <inertia ixx="0.00" ixy="0.00" ixz="0.00" iyy="0.00" iyz="0.00" izz="0.00"/>
    </inertial>
  </link>
  <joint name="propeller_l_joint" type="continuous">
    <origin rpy="0 0 3.14159265359" xyz="0.17 0 0.026"/>
    <parent link="motor_l"/>
    <child link="propeller_l"/>
  </joint>
  <link name="propeller_l">
    <visual>
      <geometry>
        <mesh filename="package://ros_ship_description/mesh/PROPELLER.dae"/>
      </geometry>
    </visual>
    <collision name="propeller_l_collision">
      <geometry>
        <mesh filename="package://ros_ship_description/mesh/PROPELLER.dae"/>
      </geometry>
    </collision>
    <inertial>
      <mass value="0.28"/>
      <inertia ixx="0.00086" ixy="0.00" ixz="0.00" iyy="0.00086" iyz="0.00" izz="0.0017"/>
    </inertial>
  </link>
  <transmission name="motor_r_trans">
    <type>transmission_interface/SimpleTransmission</type>
    <joint name="propeller_r_joint">
      <hardwareInterface>VelocityJointInterface</hardwareInterface>
    </joint>
    <actuator name="motor_r_actuator">
      <hardwareInterface>VelocityJointInterface</hardwareInterface>
      <mechanicalReduction>30</mechanicalReduction>
    </actuator>
  </transmission>
  <transmission name="motor_l_trans">
    <type>transmission_interface/SimpleTransmission</type>
    <joint name="propeller_l_joint">
      <hardwareInterface>VelocityJointInterface</hardwareInterface>
    </joint>
    <actuator name="motor_l_actuator">
      <hardwareInterface>VelocityJointInterface</hardwareInterface>
      <mechanicalReduction>30</mechanicalReduction>
    </actuator>
  </transmission>
  <gazebo>
    <plugin filename="libgazebo_ros_control.so" name="gazebo_ros_control">
      <robotNamespace>/ros_ship</robotNamespace>
    </plugin>
  </gazebo>
  <gazebo reference="camera_r">
    <sensor name="camera_r" type="camera">
      <update_rate>30.0</update_rate>
      <camera name="head">
        <horizontal_fov>1.3962634</horizontal_fov>
        <image>
          <width>640</width>
          <height>480</height>
          <format>R8G8B8</format>
        </image>
        <clip>
          <near>0.02</near>
          <far>300</far>
        </clip>
        <noise>
          <type>gaussian</type>
          <!-- Noise is sampled independently per pixel on each frame.
               That pixel's noise value is added to each of its color
               channels, which at that point lie in the range [0,1]. -->
          <mean>0.0</mean>
          <stddev>0.007</stddev>
        </noise>
      </camera>
      <plugin filename="libgazebo_ros_camera.so" name="camera_controller">
        <alwaysOn>true</alwaysOn>
        <updateRate>0.0</updateRate>
        <cameraName>ros_ship/camera_r</cameraName>
        <imageTopicName>image_raw</imageTopicName>
        <cameraInfoTopicName>camera_info</cameraInfoTopicName>
        <frameName>camera_link</frameName>
        <hackBaseline>0.07</hackBaseline>
        <distortionK1>0.0</distortionK1>
        <distortionK2>0.0</distortionK2>
        <distortionK3>0.0</distortionK3>
        <distortionT1>0.0</distortionT1>
        <distortionT2>0.0</distortionT2>
      </plugin>
    </sensor>
  </gazebo>
  <gazebo reference="camera_l">
    <sensor name="camera_l" type="camera">
      <update_rate>30.0</update_rate>
      <camera name="head">
        <horizontal_fov>1.3962634</horizontal_fov>
        <image>
          <width>640</width>
          <height>480</height>
          <format>R8G8B8</format>
        </image>
        <clip>
          <near>0.02</near>
          <far>300</far>
        </clip>
        <noise>
          <type>gaussian</type>
          <!-- Noise is sampled independently per pixel on each frame.
               That pixel's noise value is added to each of its color
               channels, which at that point lie in the range [0,1]. -->
          <mean>0.0</mean>
          <stddev>0.007</stddev>
        </noise>
      </camera>
      <plugin filename="libgazebo_ros_camera.so" name="camera_controller">
        <alwaysOn>true</alwaysOn>
        <updateRate>0.0</updateRate>
        <cameraName>ros_ship/camera_l</cameraName>
        <imageTopicName>image_raw</imageTopicName>
        <cameraInfoTopicName>camera_info</cameraInfoTopicName>
        <frameName>camera_link</frameName>
        <hackBaseline>0.07</hackBaseline>
        <distortionK1>0.0</distortionK1>
        <distortionK2>0.0</distortionK2>
        <distortionK3>0.0</distortionK3>
        <distortionT1>0.0</distortionT1>
        <distortionT2>0.0</distortionT2>
      </plugin>
    </sensor>
  </gazebo>
  <gazebo>
    <plugin filename="libunderwater_object_ros_plugin.so" name="uuv_plugin">
      <fluid_density>1028.0</fluid_density>
      <flow_velocity_topic>hydrodynamics/current_velocity</flow_velocity_topic>
    </plugin>
  </gazebo>
</robot>

