<?xml version="1.0" ?>
<!-- =================================================================================== -->
<!-- |    This document was autogenerated by xacro from wam-v.urdf.xacro               | -->
<!-- |    EDITING THIS FILE BY HAND IS NOT RECOMMENDED                                 | -->
<!-- =================================================================================== -->
<robot name="wam-v" xmlns:xacro="http://ros.org/wiki/xacro">
  <link name="base_link">
    <visual>
      <geometry>
        <mesh filename="package://ros_ship_description/mesh/WAM-V.dae"/>
      </geometry>
    </visual>
    <collision name="base_link_collision">
      <geometry>
        <mesh filename="package://ros_ship_description/mesh/WAM-V.dae"/>
      </geometry>
    </collision>
    <inertial>
      <mass value="247.07"/>
      <inertia ixx="137.35" ixy="0.03" ixz="3.09" iyy="181.69" iyz="-0.05" izz="165.39"/>
    </inertial>
  </link>
  <joint name="base_footprint_joint" type="fixed">
    <origin xyz="0 0 -1.84"/>
    <parent link="base_link"/>
    <child link="base_footprint"/>
  </joint>
  <link name="base_footprint"/>
  <link name="right_motor">
    <visual>
      <geometry>
        <mesh filename="package://ros_ship_description/mesh/PROPELLER.dae"/>
      </geometry>
    </visual>
    <collision name="right_motor_collision">
      <geometry>
        <mesh filename="package://ros_ship_description/mesh/PROPELLER.dae"/>
      </geometry>
    </collision>
    <inertial>
      <mass value="0.0001"/>
      <inertia ixx="0.00086" ixy="0.00" ixz="0.00" iyy="0.00086" iyz="0.00" izz="0.0017"/>
    </inertial>
  </link>
  <joint name="left_motor_joint" type="continuous">
    <origin xyz="-0.5 -0.75 -1.5"/>
    <parent link="base_link"/>
    <child link="left_motor"/>
  </joint>
  <link name="left_motor">
    <visual>
      <geometry>
        <mesh filename="package://ros_ship_description/mesh/PROPELLER.dae"/>
      </geometry>
    </visual>
    <collision name="left_motor_collision">
      <geometry>
        <mesh filename="package://ros_ship_description/mesh/PROPELLER.dae"/>
      </geometry>
    </collision>
    <inertial>
      <mass value="0.0001"/>
      <inertia ixx="0.00086" ixy="0.00" ixz="0.00" iyy="0.00086" iyz="0.00" izz="0.0017"/>
    </inertial>
  </link>
  <joint name="left_motor_joint" type="continuous">
    <origin xyz="-0.5 0.75 -1.5"/>
    <parent link="base_link"/>
    <child link="left_motor"/>
  </joint>
  <gazebo>
    <plugin filename="libsimple_buoyancy_plugin.so" name="simple_buoyancy">
      <target_link>base_link</target_link>
      <cob_x>0.75</cob_x>
      <cob_y>-1.05</cob_y>
      <cob_z>-1.25</cob_z>
      <bbox_x>4.0</bbox_x>
      <bbox_y>0.5</bbox_y>
      <bbox_z>0.5</bbox_z>
      <publish_data>true</publish_data>
      <bbox_prefix>right_bbox</bbox_prefix>
    </plugin>
    <plugin filename="libsimple_buoyancy_plugin.so" name="simple_buoyancy">
      <target_link>base_link</target_link>
      <cob_x>0.75</cob_x>
      <cob_y>1.05</cob_y>
      <cob_z>-1.25</cob_z>
      <bbox_x>4.0</bbox_x>
      <bbox_y>0.5</bbox_y>
      <bbox_z>0.5</bbox_z>
      <publish_data>true</publish_data>
      <bbox_prefix>left_bbox</bbox_prefix>
    </plugin>
  </gazebo>
</robot>
